Workbook

Sheet Detalle de Costos
D3: Costos por paquete de trabajo
A6: Nombre del Proyecto
A7: Código | B7: Paquete de Trabajo
A8: Semana | C8: 1 | D8: 2 | E8: 3 | F8: 4 | G8: 5 | H8: 6 | I8: 7 | J8: 8 | K8: 9 | L8: 10 | M8: 11 | N8: 12 | O8: 13 | P8: 14 | Q8: 15 | R8: 16 | S8: 17 | T8: 18 | U8: 19 | V8: 20 | W8: 21 | X8: 22 | Y8: 23 | Z8: 24 | AA8: 25 | AB8: 26 | AC8: 27 | AD8: 6 | AE8: 7 | AF8: 8 | AG8: 9 | AH8: 10 | AI8: 33 | AJ8: 34 | AK8: 35 | AL8: 36 | AM8: 37 | AN8: 38 | AO8: 39 | AP8: 40 | AQ8: 41 | AR8: 42 | AS8: 43 | AT8: 44 | AU8: 45 | AV8: 46 | AW8: 47 | AX8: 48 | AY8: 49 | AZ8: 50 | BA8: 51 | BB8: 52 | BC8: 53 | BD8: 54 | BE8: 55 | BF8: 56 | BG8: 57 | BH8: 58 | BI8: 59 | BJ8: 60
A9: Componente 1 | C9: 14000 | D9: 16000 | E9: 20000 | F9: 25000 | G9: 27000 | H9: 33000 | I9: 36000 | J9: 39000 | K9: 35000 | L9: 25000 | M9: 17000 | N9: 13000 | AD9: ='Plantilla Curva S'!I15 -> 33000 | AE9: ='Plantilla Curva S'!J15 -> 36000 | AF9: ='Plantilla Curva S'!K15 -> 39000 | AG9: ='Plantilla Curva S'!L15 -> 35000 | AH9: ='Plantilla Curva S'!M15 -> 25000
A10: 1.1.1.1 | B10: Revision de variables | C10: 2000 | D10: 2500
A11: 1.1.1.2 | B11: Validacion de formatos y consistencia | C11: 3500 | D11: 4000
A12: 1.1.1.3 | B12: Documentacion tecnica del dataset | C12: 4000 | D12: 4499
A13: 1.1.1.4 | B13: Limpieza y validacion del datatest | C13: 3000 | D13: 3000
A14: 1.1.1.5 | B14: Licencia de Ghat GPT Pro | C14: 100 | D14: 100
A15: 1.1.1.6 | B15: Consultoria de estadistica externa | C15: 1000 | D15: 1000
A16: Componente 2
A17: 2.1.1.1 | B17: Calculo de ingresos acumulados | E17: 1699 | F17: 2199
A18: 2.1.1.2 | B18: Preparacion de datos para forecasting | E18: 2000 | F18: 2499
A19: 2.1.1.3 | B19: Desarrollo del modelo predictivo | E19: 2500 | F19: 3499
A20: 2.1.2.1 | B20: Pruebas de modelo | E20: 1499 | F20: 1999
A21: 2.1..2.2 | B21: Licencia de Chat GTP Pro | E21: 100 | F21: 100
A22: 2.1.2.3 | B22: Computacion/ procesamiento | E22: 1500 | F22: 1500
A23: 2.1.3.1 | B23: Visualizacion de predicciones | E23: 2499 | F23: 2499
A24: 2.1.3.2 | B24: Analisis de resultados | E24: 1999 | F24: 2499
A25: 2.1.3.3 | B25: Documentacion tecnica | E25: 1000 | F25: 1499
A26: 2.1.4.1 | B26: Consultoria Externa | E26: 2000 | F26: 2500
A27: 2.1.4.2 | B27: Integracion del analisis del portafolio | E27: 1199 | F27: 1199
A28: Componente 3
A29: 2.1.1.1 | B29: Configuracion inicial del repositorio en Github | G29: 6000
A30: 2.1.1.2 | B30: Organización de carpetas y estructura del proyecto | G30: 4500
A31: 2.1.1.3 | B31: Carga inicial del codigo del analisis | G31: 7000 | AD31: 5400
A32: 2.1.1.4 | B32: Revision de archivos , pruebas y correcciones | G32: 6000
A33: 2.1.2.1 | B33: Documentacion basica en README | G33: 2000 | AD33: 1000
A34: 2.1.2.2 | B34: Insumos | G34: 1000 | AD34: 1000
A35: 2.2.3.1 | B35: Limpieza y preparacion de datos de ventas | H35: 7500 | AD35: 10500
A36: 2.2.3.2 | B36: Calculo de participacion por producto | H36: 8000 | AD36: 8000
A37: 2.2.3.3 | B37: Validacion de resultados | H37: 5500 | AD37: 6500
A38: 2.2.3.4 | B38: Clasificacion de productos A, B y C | H38: 7400
A39: 2.2.3..5 | B39: Revision y reporte preliminar | H39: 4000
A40: Componente 4
A41: 2.1.1.1 | B41: Analisis del crecimiento del producto | I41: 8500 | AE41: 8000
A42: 2.1.1.2 | B42: Calculo de la tasa de crecimiento | I42: 7800 | AE42: 4000
B43: Comparacion contra productos principales | I43: 7000 | AE43: 9500
B44: Revision de formulas y consistencia | I44: 6200 | AE44: 5000
...

Sheet Plantilla Curva S
C7: Curva S de Recursos
C9: Proyecto: | D9: Analisis de Portafolio de Productos
C10: ID: | D10: APP-EST-015
C11: Fecha de Inicio | D11: 46054 | F11: Fecha Fin: | H11: Fecha estimada de fin del proyecto. | K11: Fecha de Corte: | M11: Fecha a la cual se reporta el costo real.
D13: Trimestre
C14: Semana | D14: 1 | E14: 2 | F14: 3 | G14: 4 | H14: 5 | I14: 6 | J14: 7 | K14: 8 | L14: 9 | M14: 10 | N14: 11 | O14: 12
C15: Valor Planificado | D15: ='Detalle de Costos'!C9 -> 14000 | E15: ='Detalle de Costos'!D9 -> 16000 | F15: ='Detalle de Costos'!E9 -> 20000 | G15: ='Detalle de Costos'!F9 -> 25000 | H15: ='Detalle de Costos'!G9 -> 27000 | I15: ='Detalle de Costos'!H9 -> 33000 | J15: ='Detalle de Costos'!I9 -> 36000 | K15: ='Detalle de Costos'!J9 -> 39000 | ... O15: ='Detalle de Costos'!N9 -> 13000
C16: Valor Planificado Acumulado | D16: =D15 -> 14000 | E16: =E15+D16 -> 30000 | F16: =F15+E16 -> 50000 | G16: =G15+F16 -> 75000 | H16: =H15+G16 -> 102000 | I16: =I15+H16 -> 135000 | J16: =J15+I16 -> 171000 | K16: =K15+J16 -> 210000 | L16: =L15+K16 -> 245000 | ... O16: =O15+N16 -> 300000
C17: Costo Real | D17: ='Detalle de Costos'!C73 -> 13600 | E17: ='Detalle de Costos'!D73 -> 15099 | F17: ='Detalle de Costos'!E73 -> 17995 | G17: ='Detalle de Costos'!F73 -> 21992 | H17: ='Detalle de Costos'!G73 -> 26500 | I17: ='Detalle de Costos'!H73 -> 32400 | J17: ='Detalle de Costos'!I73 -> 35200 | K17: ='Detalle de Costos'!J73 -> 38100 | ... O17: ='Detalle de Costos'!N73 -> 12700
C18: Costo Real Acumulado | D18: =D17 -> 13600 | E18: =D18+E17 -> 28699 | F18: =E18+F17 -> 46694 | G18: =F18+G17 -> 68686 | H18: =G18+H17 -> 95186 | I18: =H18+I17 -> 127586 | J18: =I18+J17 -> 162786 | K18: =J18+K17 -> 200886 | L18: =K18+L17 -> 235486 | ... O18: =N18+O17 -> 289686

Sheet Ejemplo
C7: Curva S de Recursos
C9: Proyecto: | D9: Apoyo Educativo
C10: ID: | D10: HT2011-12
C11: Fecha de Inicio | D11: 40695 | F11: Fecha Fin: | H11: 41455 | K11: Fecha de Corte: | M11: 40908
D13: Año 2012
D14: 1 | E14: 2 | F14: 3 | G14: 4 | H14: 5 | I14: 6 | J14: 7 | K14: 8 | L14: 9 | M14: 10 | N14: 11 | O14: 12
C15: Valor Planificado | D15: 20000 | E15: 40000 | F15: 60000 | G15: 80000 | H15: 120000 | I15: 140000 | J15: 160000 | K15: 180000 | L15: 180000 | M15: 120000 | N15: 80000 | O15: 40000
C16: Valor Planificado Acumulado | D16: =D15 -> 20000 | E16: =D16+E15 -> 60000 | F16: =E16+F15 -> 120000 | G16: =F16+G15 -> 200000 | H16: =G16+H15 -> 320000 | I16: =H16+I15 -> 460000 | J16: =I16+J15 -> 620000 | K16: =J16+K15 -> 800000 | L16: =K16+L15 -> 980000 | ... O16: =N16+O15 -> 1220000
C17: Costo Real | D17: 20000 | E17: 20000 | F17: 40000 | G17: 60000 | H17: 80000 | I17: 100000 | J17: 150000
C18: Costo Real Acumulado | D18: =D17 -> 20000 | E18: =D18+E17 -> 40000 | F18: =E18+F17 -> 80000 | G18: =F18+G17 -> 140000 | H18: =G18+H17 -> 220000 | I18: =H18+I17 -> 320000 | J18: =I18+J17 -> 470000
